Workbook

Sheet Resultats+Estadístics
B4: Escenari 1
C5: Rèplica (Seed) | D5: Benefici
C6: 1 | D6: 241919
C7: 2 | D7: 241420
C8: 3 | D8: 238351
C9: 4 | D9: 239777.5
C10: 5 | D10: 236816
C11: 6 | D11: 238762.5
C12: 7 | D12: 239522.5
C13: 8 | D13: 235453
C14: 9 | D14: 239626
C15: 10 | D15: 239697
D17: Mitjana | E17: Variància | F17: Interval de confiança del 95% | G17: Semiamplitud de l'interval de confiança | H17: 5% del valor mitjà
D18: =AVERAGE(D6:D15) -> 239134.45 | E18: =VAR(D6:D15) -> 3753340.3 | F18: =D18-G18 -> 237748.55 | G18: =_xlfn.CONFIDENCE.T(0.05,SQRT(E18),COUNT(D6:D15)) -> 1385.8995 | H18: =5%*D18 -> 11956.722
F19: =D18+G18 -> 240520.35
B23: Escenari 2
C24: Rèplica (Seed) | D24: Benefici
C25: 1 | D25: 68780.5
C26: 2 | D26: 70630
C27: 3 | D27: 68179.5
C28: 4 | D28: 67900.5
C29: 5 | D29: 69170.5
C30: 6 | D30: 70332
C31: 7 | D31: 67409
C32: 8 | D32: 69569.5
C33: 9 | D33: 69096
C34: 10 | D34: 69535
D36: Mitjana | E36: Variància | F36: Interval de confiança del 95% | G36: Semiamplitud de l'interval de confiança | H36: 5% del valor mitjà
D37: =AVERAGE(D25:D34) -> 69060.25 | E37: =VAR(D25:D34) -> 1056138.5 | F37: =D37-G37 -> 68325.088 | G37: =_xlfn.CONFIDENCE.T(0.05,SQRT(E37),COUNT(D25:D34)) -> 735.16228 | H37: =5%*D37 -> 3453.0125
F38: =D37+G37 -> 69795.412
B42: Escenari 3
C43: Rèplica (Seed) | D43: Benefici
C44: 1 | D44: -49959.5
C45: 2 | D45: -48688
C46: 3 | D46: -46098.5
C47: 4 | D47: -46655
C48: 5 | D48: -50177.5
C49: 6 | D49: -50459.5
C50: 7 | D50: -49504.5
C51: 8 | D51: -50527.5
...

Sheet Yates
B2: Taula del disseny factorial | D2: *0 nivell baix | I2: Algorisme de Yates
D3: *1 nivell alt | H3: *Benefici de l'escenari 8 és després de fer 12000 rèpliques
C4: Escenari | D4: Temps Total (A) | E4: Nº Màquines (B) | F4: Interval entre paquets (C) | G4: Màquines Ràpides (D) | H4: Beneficis | I4: Aux1 | J4: Aux2 | K4: Aux3 | L4: Aux4 | M4: Div | N4: Efecte | O4: Combinació
C5: 1 | D5: 0 | E5: 0 | F5: 0 | G5: 0 | H5: ='Resultats+Estadístics'!D18 -> 239134.45 | I5: =SUM(H5:H6) -> 308194.7 | J5: =SUM(I5:I6) -> 184529.45 | K5: =SUM(J5:J6) -> 715839.65 | L5: =SUM(K5:K6) -> 1950572.1 | M5: 16 | N5: =L5/M5 -> 121910.76 | O5: Mitjana
C6: 2 | D6: 1 | E6: 0 | F6: 0 | G6: 0 | H6: ='Resultats+Estadístics'!D37 -> 69060.25 | I6: =SUM(H7:H8) -> -123665.25 | J6: =SUM(I7:I8) -> 531310.2 | K6: =SUM(J7:J8) -> 1234732.5 | L6: =SUM(K7:K8) -> -1183334.2 | M6: 8 | N6: =L6/M6 -> -147916.78 | O6: A
C7: 3 | D7: 0 | E7: 1 | F7: 0 | G7: 0 | H7: ='Resultats+Estadístics'!D56 -> -48460.55 | I7: =sum(H9:H10) -> 480331.9 | J7: =sum(I9:I10) -> 459178.6 | K7: =sum(J9:J10) -> -445573.55 | L7: =sum(K9:K10) -> -1574985.6 | M7: 8 | N7: =L7/M7 -> -196873.21 | O7: B
C8: 4 | D8: 1 | E8: 1 | F8: 0 | G8: 0 | H8: ='Resultats+Estadístics'!D75 -> -75204.7 | I8: =sum(H11:H12) -> 50978.3 | J8: =sum(I11:I12) -> 775553.9 | K8: =sum(J11:J12) -> -737760.7 | L8: =sum(K11:K12) -> 585387.95 | M8: 8 | N8: =L8/M8 -> 73173.494 | O8: AB
C9: 5 | D9: 0 | E9: 0 | F9: 1 | G9: 0 | H9: ='Resultats+Estadístics'!D94 -> 339234.35 | I9: =sum(H13:H14) -> 445424.9 | J9: =sum(I13:I14) -> -196818.35 | K9: =sum(J13:J14) -> -861213.55 | L9: =sum(K13:K14) -> 663156.05 | M9: 8 | N9: =L9/M9 -> 82894.506 | O9: C
C10: 6 | D10: 1 | E10: 0 | F10: 1 | G10: 0 | H10: ='Resultats+Estadístics'!D113 -> 141097.55 | I10: =sum(H15:H16) -> 13753.7 | J10: =sum(I15:I16) -> -248755.2 | K10: =sum(J15:J16) -> -713772.1 | L10: =sum(K15:K16) -> -126653.95 | M10: 8 | N10: =L10/M10 -> -15831.744 | O10: AC
C11: 7 | D11: 0 | E11: 1 | F11: 1 | G11: 0 | H11: ='Resultats+Estadístics'!D132 -> 50798.35 | I11: =sum(H17:H18) -> 528827.4 | J11: =sum(I17:I18) -> -331521.8 | K11: =sum(J17:J18) -> 290848.45 | L11: =sum(K17:K18) -> 152076.65 | M11: 8 | N11: =L11/M11 -> 19009.581 | O11: BC
C12: 8 | D12: 1 | E12: 1 | F12: 1 | G12: 0 | H12: ='Resultats+Estadístics'!J158 -> 179.95 | I12: =sum(H19:H20) -> 246726.5 | J12: =sum(I19:I20) -> -406238.9 | K12: =sum(J19:J20) -> 294539.5 | L12: =sum(K19:K20) -> 9932.65 | M12: 8 | N12: =L12/M12 -> 1241.5812 | O12: ABC
C13: 9 | D13: 0 | E13: 0 | F13: 0 | G13: 1 | H13: ='Resultats+Estadístics'!D170 -> 341692.3 | I13: =H6-H5 -> -170074.2 | J13: =I6-I5 -> -431859.95 | K13: =J6-J5 -> 346780.75 | L13: =K6-K5 -> 518892.85 | M13: 8 | N13: =L13/M13 -> 64861.606 | O13: D
C14: 10 | D14: 1 | E14: 0 | F14: 0 | G14: 1 | H14: ='Resultats+Estadístics'!D189 -> 103732.6 | I14: =H8-H7 -> -26744.15 | J14: =I8-I7 -> -429353.6 | K14: =J8-J7 -> 316375.3 | L14: =K8-K7 -> -292187.15 | M14: 8 | N14: =L14/M14 -> -36523.394 | O14: AD
C15: 11 | D15: 0 | E15: 1 | F15: 0 | G15: 1 | H15: ='Resultats+Estadístics'!D208 -> 53657.9 | I15: =H10-H9 -> -198136.8 | J15: =I10-I9 -> -431671.2 | K15: =J10-J9 -> -51936.85 | L15: =K10-K9 -> 147441.45 | M15: 8 | N15: =L15/M15 -> 18430.181 | O15: BD
C16: 12 | D16: 1 | E16: 1 | F16: 0 | G16: 1 | H16: ='Resultats+Estadístics'!D227 -> -39904.2 | I16: =H12-H11 -> -50618.4 | J16: =I12-I11 -> -282100.9 | K16: =J12-J11 -> -74717.1 | L16: =K12-K11 -> 3691.05 | M16: 8 | N16: =L16/M16 -> 461.38125 | O16: ABD
C17: 13 | D17: 0 | E17: 0 | F17: 1 | G17: 1 | H17: ='Resultats+Estadístics'!D246 -> 403508.9 | I17: =H14-H13 -> -237959.7 | J17: =I14-I13 -> 143330.05 | K17: =J14-J13 -> 2506.35 | L17: =K14-K13 -> -30405.45 | M17: 8 | N17: =L17/M17 -> -3800.6813 | O17: CD
C18: 14 | D18: 1 | E18: 0 | F18: 1 | G18: 1 | H18: ='Resultats+Estadístics'!D265 -> 125318.5 | I18: =H16-H15 -> -93562.1 | J18: =I16-I15 -> 147518.4 | K18: =J16-J15 -> 149570.3 | L18: =K16-K15 -> -22780.25 | M18: 8 | N18: =L18/M18 -> -2847.5312 | O18: ACD
C19: 15 | D19: 0 | E19: 1 | F19: 1 | G19: 1 | H19: ='Resultats+Estadístics'!D284 -> 187387.5 | I19: =H18-H17 -> -278190.4 | J19: =I18-I17 -> 144397.6 | K19: =J18-J17 -> 4188.35 | L19: =K18-K17 -> 147063.95 | M19: 8 | N19: =L19/M19 -> 18382.994 | O19: BCD
C20: 16 | D20: 1 | E20: 1 | F20: 1 | G20: 1 | H20: ='Resultats+Estadístics'!D303 -> 59339 | I20: =H20-H19 -> -128048.5 | J20: =I20-I19 -> 150141.9 | K20: =J20-J19 -> 5744.3 | L20: =K20-K19 -> 1555.95 | M20: 8 | N20: =L20/M20 -> 194.49375 | O20: ABCD
